Workbook

Sheet Final
A1: Trialno | B1: ConceptNo | C1: Concept | D1: FeatureNo | E1: Feature
A2: 1 | B2: f12 | C2: alma | D2: feat02 | E2: LEHET_ESZIK
A3: 2 | B3: f12 | C3: alma | D3: feat60 | E3: HOL_KERT
A4: 3 | B4: f12 | C4: alma | D4: feat09 | E4: ILYEN_PIROS
A5: 4 | B5: f12 | C5: alma | D5: feat20 | E5: ALFAJTA_ZÖLD
A6: 5 | B6: f12 | C6: alma | D6: feat07 | E6: FAJTA_GYÜMÖLCS
A7: 6 | B7: f12 | C7: alma | D7: feat180 | E7: ILYEN_EGÉSZSÉGES
A8: 7 | B8: f12 | C8: alma | D8: feat182 | E8: ILYEN_KÖRALAKÚ
A9: 8 | B9: f12 | C9: alma | D9: feat40 | E9: HOL_PIAC
A10: 9 | B10: f12 | C10: alma | D10: feat59 | E10: HOL_FA
A11: 10 | B11: f12 | C11: alma | D11: feat21 | E11: ILYEN_FINOM
A12: 1 | B12: t17 | C12: asztal | D12: feat23 | E12: MIBŐL_FA
A13: 2 | B13: t17 | C13: asztal | D13: feat14 | E13: NÉGY_LÁB
... A300: 10 | B300: v04 | C300: vonat | D300: feat133 | E300: TUD_SZÁLLÍT

Sheet Curation
A2: MRNGO Feature Curation — 10-Item Lists | J2: How to curate:
A3: Add up to 10 features per concept. Use the FeaturePool sheet to browse and copy available features.
J4: 1. Go to the FeaturePool sheet to browse all features for a concept.
A5: Concept | B5: Conceptno | C5: featureno | D5: Feature | E5: Freq (concept) | F5: Distinct | G5: Item # | H5: Notes | J5: 2. Copy featureno and Feature into the matching rows here.
A6: alma | B6: f12 | C6: feat02 | D6: LEHET_ESZIK | E6: =VLOOKUP(C6,FeaturePool!$C$6:$F$26,3,FALSE) -> 6 | F6: =VLOOKUP(C6,FeaturePool!$C$6:$F$26,4,FALSE) -> 0.125 | G6: 1 | J6: 3. Filled rows will highlight green automatically.
B7: f12 | C7: feat60 | D7: HOL_KERT | E7: =VLOOKUP(C7,FeaturePool!$C$6:$F$26,3,FALSE) -> 2 | F7: =VLOOKUP(C7,FeaturePool!$C$6:$F$26,4,FALSE) -> 0.111 | G7: 2
B8: f12 | C8: feat09 | D8: ILYEN_PIROS | E8: =VLOOKUP(C8,FeaturePool!$C$6:$F$26,3,FALSE) -> 15 | F8: =VLOOKUP(C8,FeaturePool!$C$6:$F$26,4,FALSE) -> 0.125 | G8: 3 | H8: switched these
B9: f12 | C9: feat20 | D9: ALFAJTA_ZÖLD | E9: =VLOOKUP(C9,FeaturePool!$C$6:$F$26,3,FALSE) -> 13 | F9: =VLOOKUP(C9,FeaturePool!$C$6:$F$26,4,FALSE) -> 0.111 | G9: 4 | H9: switched these, it's not possible to figure out without the colour
B10: f12 | C10: feat07 | D10: FAJTA_GYÜMÖLCS | E10: =VLOOKUP(C10,FeaturePool!$C$6:$F$26,3,FALSE) -> 12 | F10: =VLOOKUP(C10,FeaturePool!$C$6:$F$26,4,FALSE) -> 0.25 | G10: 5
B11: f12 | C11: feat180 | D11: ILYEN_EGÉSZSÉGES | E11: =VLOOKUP(C11,FeaturePool!$C$6:$F$26,3,FALSE) -> 2 | F11: =VLOOKUP(C11,FeaturePool!$C$6:$F$26,4,FALSE) -> 0.2 | G11: 6
B12: f12 | C12: feat182 | D12: ILYEN_KÖRALAKÚ | E12: =VLOOKUP(C12,FeaturePool!$C$6:$F$26,3,FALSE) -> 2 | F12: =VLOOKUP(C12,FeaturePool!$C$6:$F$26,4,FALSE) -> 0.2 | G12: 7
B13: f12 | C13: feat40 | D13: HOL_PIAC | E13: =VLOOKUP(C13,FeaturePool!$C$6:$F$26,3,FALSE) -> 2 | F13: =VLOOKUP(C13,FeaturePool!$C$6:$F$26,4,FALSE) -> 0.091 | G13: 8
B14: f12 | C14: feat59 | D14: HOL_FA | E14: =VLOOKUP(C14,FeaturePool!$C$6:$F$26,3,FALSE) -> 11 | F14: =VLOOKUP(C14,FeaturePool!$C$6:$F$26,4,FALSE) -> 0.2 | G14: 9 | H14: with these
B15: f12 | C15: feat21 | D15: ILYEN_FINOM | E15: =VLOOKUP(C15,FeaturePool!$C$6:$F$26,3,FALSE) -> 7 | F15: =VLOOKUP(C15,FeaturePool!$C$6:$F$26,4,FALSE) -> 0.2 | G15: 10 | H15: with these
A17: asztal | B17: t17 | C17: feat23 | D17: MIBŐL_FA | E17: =VLOOKUP(C17,FeaturePool!$C$26:$F$44,3,FALSE) -> 9 | F17: =VLOOKUP(C17,FeaturePool!$C$26:$F$44,4,FALSE) -> 0.167 | G17: 1
B18: t17 | C18: feat14 | D18: NÉGY_LÁB | E18: =VLOOKUP(C18,FeaturePool!$C$26:$F$44,3,FALSE) -> 12 | F18: =VLOOKUP(C18,FeaturePool!$C$26:$F$44,4,FALSE) -> 0.333 | G18: 2 | H18: these first two should be after each other I think
B19: t17 | C19: feat39 | D19: HOL_ISKOLA | E19: =VLOOKUP(C19,FeaturePool!$C$26:$F$44,3,FALSE) -> 3 | F19: =VLOOKUP(C19,FeaturePool!$C$26:$F$44,4,FALSE) -> 0.143 | G19: 3
B20: t17 | C20: feat97 | D20: BENNE_ESZIK | E20: =VLOOKUP(C20,FeaturePool!$C$26:$F$44,3,FALSE) -> 11 | F20: =VLOOKUP(C20,FeaturePool!$C$26:$F$44,4,FALSE) -> 0.333 | G20: 4
B21: t17 | C21: feat71 | D21: FAJTA_TÁRGY | E21: =VLOOKUP(C21,FeaturePool!$C$26:$F$44,3,FALSE) -> 5 | F21: =VLOOKUP(C21,FeaturePool!$C$26:$F$44,4,FALSE) -> 0.125 | G21: 5
B22: t17 | C22: feat06 | D22: HOL_HÁZ | E22: =VLOOKUP(C22,FeaturePool!$C$26:$F$44,3,FALSE) -> 7 | F22: =VLOOKUP(C22,FeaturePool!$C$26:$F$44,4,FALSE) -> 0.083 | G22: 6
B23: t17 | C23: feat32 | D23: LEHET_RAJZOL | E23: =VLOOKUP(C23,FeaturePool!$C$26:$F$44,3,FALSE) -> 5 | F23: =VLOOKUP(C23,FeaturePool!$C$26:$F$44,4,FALSE) -> 0.25 | G23: 7
B24: t17 | C24: feat29 | D24: LEHET_ÍR | E24: =VLOOKUP(C24,FeaturePool!$C$26:$F$44,3,FALSE) -> 3 | F24: =VLOOKUP(C24,FeaturePool!$C$26:$F$44,4,FALSE) -> 0.2 | G24: 8
B25: t17 | C25: feat151 | D25: HOL_LAKÁS | E25: =VLOOKUP(C25,FeaturePool!$C$26:$F$44,3,FALSE) -> 2 | F25: =VLOOKUP(C25,FeaturePool!$C$26:$F$44,4,FALSE) -> 0.25 | G25: 9
B26: t17 | C26: feat158 | D26: LEHET_RÁTESZ | E26: =VLOOKUP(C26,FeaturePool!$C$26:$F$44,3,FALSE) -> 11 | F26: =VLOOKUP(C26,FeaturePool!$C$26:$F$44,4,FALSE) -> 0.25 | G26: 10
A28: autó | B28: v13 | C28: feat44 | D28: RÉSZE_KERÉK | E28: =VLOOKUP(C28,FeaturePool!$C$45:$F$66,3,FALSE) -> 11 | F28: =VLOOKUP(C28,FeaturePool!$C$45:$F$66,4,FALSE) -> 0.333 | G28: 1
C29: feat265 | D29: TUD_GURUL | E29: =VLOOKUP(C29,FeaturePool!$C$45:$F$66,3,FALSE) -> 3 | F29: =VLOOKUP(C29,FeaturePool!$C$45:$F$66,4,FALSE) -> 0.333 | G29: 2
C30: feat55 | D30: ILYEN_GYORS | E30: =VLOOKUP(C30,FeaturePool!$C$45:$F$66,3,FALSE) -> 3 | F30: =VLOOKUP(C30,FeaturePool!$C$45:$F$66,4,FALSE) -> 0.143 | G30: 3
C31: feat10 | D31: MIBŐL_FÉM | E31: =VLOOKUP(C31,FeaturePool!$C$45:$F$66,3,FALSE) -> 10 | F31: =VLOOKUP(C31,FeaturePool!$C$45:$F$66,4,FALSE) -> 0.2 | G31: 4
C32: feat70 | D32: FAJTA_JÁRMŰ | E32: =VLOOKUP(C32,FeaturePool!$C$45:$F$66,3,FALSE) -> 6 | F32: =VLOOKUP(C32,FeaturePool!$C$45:$F$66,4,FALSE) -> 0.333 | G32: 5
C33: feat81 | D33: LEHET_ÜL | E33: =VLOOKUP(C33,FeaturePool!$C$45:$F$66,3,FALSE) -> 5 | F33: =VLOOKUP(C33,FeaturePool!$C$45:$F$66,4,FALSE) -> 0.2 | G33: 6
C34: feat133 | D34: TUD_SZÁLLÍT | E34: =VLOOKUP(C34,FeaturePool!$C$45:$F$66,3,FALSE) -> 2 | F34: =VLOOKUP(C34,FeaturePool!$C$45:$F$66,4,FALSE) -> 0.25 | G34: 7
C35: feat04 | D35: ILYEN_NAGY | E35: =VLOOKUP(C35,FeaturePool!$C$45:$F$66,3,FALSE) -> 1 | F35: =VLOOKUP(C35,FeaturePool!$C$45:$F$66,4,FALSE) -> 0.05 | G35: 8
C36: feat251 | D36: HOL_ÚT | E36: =VLOOKUP(C36,FeaturePool!$C$45:$F$66,3,FALSE) -> 2 | F36: =VLOOKUP(C36,FeaturePool!$C$45:$F$66,4,FALSE) -> 0.25 | G36: 9
C37: feat130 | D37: LEHET_VEZET | E37: =VLOOKUP(C37,FeaturePool!$C$45:$F$66,3,FALSE) -> 5 | F37: =VLOOKUP(C37,FeaturePool!$C$45:$F$66,4,FALSE) -> 0.2 | G37: 10
A39: bab | B39: pl24 | C39: feat02 | D39: LEHET_ESZIK | E39: =VLOOKUP(C39,FeaturePool!$C$67:$F$89,3,FALSE) -> 11 | F39: =VLOOKUP(C39,FeaturePool!$C$67:$F$89,4,FALSE) -> 0.125 | G39: 1
C40: feat98 | D40: FAJTA_ZÖLDSÉG | E40: =VLOOKUP(C40,FeaturePool!$C$67:$F$89,3,FALSE) -> 2 | F40: =VLOOKUP(C40,FeaturePool!$C$67:$F$89,4,FALSE) -> 0.25 | G40: 2
C41: feat30 | D41: ILYEN_KICSI | E41: =VLOOKUP(C41,FeaturePool!$C$67:$F$89,3,FALSE) -> 5 | F41: =VLOOKUP(C41,FeaturePool!$C$67:$F$89,4,FALSE) -> 0.1 | G41: 3
C42: feat05 | D42: ILYEN_BARNA | E42: =VLOOKUP(C42,FeaturePool!$C$67:$F$89,3,FALSE) -> 11 | F42: =VLOOKUP(C42,FeaturePool!$C$67:$F$89,4,FALSE) -> 0.091 | G42: 4
C43: feat21 | D43: ILYEN_FINOM | E43: =VLOOKUP(C43,FeaturePool!$C$67:$F$89,3,FALSE) -> 2 | F43: =VLOOKUP(C43,FeaturePool!$C$67:$F$89,4,FALSE) -> 0.2 | G43: 5
C44: feat60 | D44: HOL_KERT | E44: =VLOOKUP(C44,FeaturePool!$C$67:$F$89,3,FALSE) -> 2 | F44: =VLOOKUP(C44,FeaturePool!$C$67:$F$89,4,FALSE) -> 0.111 | G44: 6
...

Sheet FeaturePool
A2: Feature Pool — Browse All Features Per Concept
A3: Sorted by Concept, then Rank_PF (most frequent first). Copy featureno + Feature to the Curation sheet.
A5: Concept | B5: Conceptno | C5: featureno | D5: Feature | E5: Freq (concept) | F5: Distinct | G5: Rank2 | H5: CV
A6: alma | B6: f12 | C6: feat09 | D6: ILYEN_PIROS | E6: 15 | F6: 0.125 | G6: 1 | H6: 0.405
A7: alma | B7: f12 | C7: feat07 | D7: FAJTA_GYÜMÖLCS | E7: 12 | F7: 0.25 | G7: 2 | H7: 0.324
A8: alma | B8: f12 | C8: feat20 | D8: ALFAJTA_ZÖLD | E8: 13 | F8: 0.111 | G8: 3 | H8: 0.423
A9: alma | B9: f12 | C9: feat59 | D9: HOL_FA | E9: 11 | F9: 0.2 | G9: 3 | H9: 0.647
A10: alma | B10: f12 | C10: feat21 | D10: ILYEN_FINOM | E10: 7 | F10: 0.2 | G10: 6 | H10: 0.269
A11: alma | B11: f12 | C11: feat15 | D11: RÉSZE_SZÁR | E11: 7 | F11: 0.2 | G11: 6 | H11: 0.233
A12: alma | B12: f12 | C12: feat02 | D12: LEHET_ESZIK | E12: 6 | F12: 0.125 | G12: 7 | H12: 0.088
A13: alma | B13: f12 | C13: feat17 | D13: ILYEN_SÁRGA | E13: 5 | F13: 0.167 | G13: 8 | H13: 0.179
A14: alma | B14: f12 | C14: feat193 | D14: RÉSZE_LEVÉL | E14: 4 | F14: 0.333 | G14: 9 | H14: 0.5
A15: alma | B15: f12 | C15: feat45 | D15: RÉSZE_MAG | E15: 5 | F15: 0.333 | G15: 10 | H15: 0.15
A16: alma | B16: f12 | C16: feat24 | D16: RÉSZE_BELSŐ | E16: 2 | F16: 0.091 | G16: 11 | H16: 0.077
A17: alma | B17: f12 | C17: feat60 | D17: HOL_KERT | E17: 2 | F17: 0.111 | G17: 11 | H17: 0.118
... A622: vonat | B622: v04 | C622: feat130 | D622: LEHET_VEZET | E622: 1 | F622: 0.2 | G622: 10 | H622: 0.091

Sheet Progress
A2: Curation Progress
A4: Concept | B4: Conceptno | C4: Items Curated | D4: Complete? | E4: Curation Sheet Row
A5: alma | B5: f12 | C5: =COUNTA(Curation!D6:D15) -> 10 | D5: =IF(C5=10,"✓ Done","Pending") -> ✓ Done | E5: Row 6–15
A6: asztal | B6: t17 | C6: =COUNTA(Curation!D17:D26) -> 10 | D6: =IF(C6=10,"✓ Done","Pending") -> ✓ Done | E6: Row 17–26
A7: autó | B7: v13 | C7: =COUNTA(Curation!D28:D37) -> 10 | D7: =IF(C7=10,"✓ Done","Pending") -> ✓ Done | E7: Row 28–37
A8: bab | B8: pl24 | C8: =COUNTA(Curation!D39:D48) -> 10 | D8: =IF(C8=10,"✓ Done","Pending") -> ✓ Done | E8: Row 39–48
A9: ceruza | B9: ty07 | C9: =COUNTA(Curation!D50:D59) -> 10 | D9: =IF(C9=10,"✓ Done","Pending") -> ✓ Done | E9: Row 50–59
A10: cipő | B10: c13 | C10: =COUNTA(Curation!D61:D70) -> 10 | D10: =IF(C10=10,"✓ Done","Pending") -> ✓ Done | E10: Row 61–70
A11: citrom | B11: f15 | C11: =COUNTA(Curation!D72:D81) -> 10 | D11: =IF(C11=10,"✓ Done","Pending") -> ✓ Done | E11: Row 72–81
A12: eper | B12: f17 | C12: =COUNTA(Curation!D83:D92) -> 10 | D12: =IF(C12=10,"✓ Done","Pending") -> ✓ Done | E12: Row 83–92
A13: erdő | B13: l23 | C13: =COUNTA(Curation!D94:D103) -> 10 | D13: =IF(C13=10,"✓ Done","Pending") -> ✓ Done | E13: Row 94–103
A14: gomba | B14: pl11 | C14: =COUNTA(Curation!D105:D114) -> 10 | D14: =IF(C14=10,"✓ Done","Pending") -> ✓ Done | E14: Row 105–114
A15: gyerek | B15: p13 | C15: =COUNTA(Curation!D117:D125) -> 9 | D15: =IF(C15=10,"✓ Done","Pending") -> Pending | E15: Row 116–125
A16: helikopter | B16: v03 | C16: =COUNTA(Curation!D127:D136) -> 10 | D16: =IF(C16=10,"✓ Done","Pending") -> ✓ Done | E16: Row 127–136
A17: hercegnő | B17: p35 | C17: =COUNTA(Curation!D138:D147) -> 10 | D17: =IF(C17=10,"✓ Done","Pending") -> ✓ Done | E17: Row 138–147
A18: játszótér | B18: l02 | C18: =COUNTA(Curation!D149:D158) -> 10 | D18: =IF(C18=10,"✓ Done","Pending") -> ✓ Done | E18: Row 149–158
A19: kacsa | B19: a05 | C19: =COUNTA(Curation!D160:D169) -> 10 | D19: =IF(C19=10,"✓ Done","Pending") -> ✓ Done | E19: Row 160–169
A20: kard | B20: ty12 | C20: =COUNTA(Curation!D171:D180) -> 9 | D20: =IF(C20=10,"✓ Done","Pending") -> Pending | E20: Row 171–180
A21: krumpli | B21: pl22 | C21: =COUNTA(Curation!D182:D191) -> 10 | D21: =IF(C21=10,"✓ Done","Pending") -> ✓ Done | E21: Row 182–191
A22: kutya | B22: a16 | C22: =COUNTA(Curation!D193:D202) -> 10 | D22: =IF(C22=10,"✓ Done","Pending") -> ✓ Done | E22: Row 193–202
A23: kéz | B23: b10 | C23: =COUNTA(Curation!D204:D213) -> 10 | D23: =IF(C23=10,"✓ Done","Pending") -> ✓ Done | E23: Row 204–213
A24: könyv | B24: ty10 | C24: =COUNTA(Curation!D215:D224) -> 10 | D24: =IF(C24=10,"✓ Done","Pending") -> ✓ Done | E24: Row 215–224
A25: láb | B25: b11 | C25: =COUNTA(Curation!D226:D235) -> 10 | D25: =IF(C25=10,"✓ Done","Pending") -> ✓ Done | E25: Row 226–235
A26: ló | B26: a19 | C26: =COUNTA(Curation!D237:D246) -> 10 | D26: =IF(C26=10,"✓ Done","Pending") -> ✓ Done | E26: Row 237–246
A27: nadrág | B27: c10 | C27: =COUNTA(Curation!D248:D257) -> 10 | D27: =IF(C27=10,"✓ Done","Pending") -> ✓ Done | E27: Row 248–257
A28: nappali | B28: l12 | C28: =COUNTA(Curation!D259:D268) -> 10 | D28: =IF(C28=10,"✓ Done","Pending") -> ✓ Done | E28: Row 259–268
A29: pulóver | B29: c28 | C29: =COUNTA(Curation!D270:D279) -> 10 | D29: =IF(C29=10,"✓ Done","Pending") -> ✓ Done | E29: Row 270–279
A30: seprű | B30: t24 | C30: =COUNTA(Curation!D281:D290) -> 10 | D30: =IF(C30=10,"✓ Done","Pending") -> ✓ Done | E30: Row 281–290
A31: szem | B31: b02 | C31: =COUNTA(Curation!D292:D301) -> 10 | D31: =IF(C31=10,"✓ Done","Pending") -> ✓ Done | E31: Row 292–301
A32: szőnyeg | B32: t20 | C32: =COUNTA(Curation!D304:D312) -> 9 | D32: =IF(C32=10,"✓ Done","Pending") -> Pending | E32: Row 303–312
A33: tűzoltó | B33: p20 | C33: =COUNTA(Curation!D314:D323) -> 10 | D33: =IF(C33=10,"✓ Done","Pending") -> ✓ Done | E33: Row 314–323
A34: vonat | B34: v04 | C34: =COUNTA(Curation!D325:D334) -> 10 | D34: =IF(C34=10,"✓ Done","Pending") -> ✓ Done | E34: Row 325–334
A36: Total completed: | C36: =COUNTIF(C5:C34,10) -> 27 | D36: =CONCATENATE(C36," / 30") -> 27 / 30

Sheet Viz
A1: Concept | B1: FeatureNo | C1: Frequency | D1: Distinct | F1: Concepts | G1: feature1 | H1: feature2 | I1: feature3 | J1: feature4 | K1: feature5 | L1: feature6 | M1: feature7 | N1: feature8 | O1: feature9 | P1: feature10 | T1: Concepts | U1: feature1 | V1: feature2 | W1: feature3 | X1: feature4 | Y1: feature5 | Z1: feature6 | AA1: feature7 | AB1: feature8 | AC1: feature9 | AD1: feature10
A2: {=_xlfn.LET(_xlpm.n,ROWS(A$2:A2),_xlpm.block,QUOTIENT(_xlpm.n-1,10),_xlpm.conceptRow,6+_xlpm.block*11,IF(INDEX(Curation!$A:$A,_xlpm.conceptRow)="","",INDEX(Curation!$A:$A,_xlpm.conceptRow)))} -> alma | B2: feature1 | C2: {=_xlfn.LET(_xlpm.n,ROWS(C$2:C2),_xlpm.block,QUOTIENT(_xlpm.n-1,10),_xlpm.pos,MOD(_xlpm.n-1,10),_xlpm.conceptRow,6+_xlpm.block*11,_xlpm.srcRow,_xlpm.conceptRow+_xlpm.pos,IF(INDEX(Curation!$A:$A,_xlpm.conceptRow)="","",INDEX(Curation!$E:$E,_xlpm.srcRow)))} -> 6 | D2: {=_xlfn.LET(_xlpm.n,ROWS(D$2:D2),_xlpm.block,QUOTIENT(_xlpm.n-1,10),_xlpm.pos,MOD(_xlpm.n-1,10),_xlpm.conceptRow,6+_xlpm.block*11,_xlpm.srcRow,_xlpm.conceptRow+_xlpm.pos,IF(INDEX(Curation!$A:$A,_xlpm.conceptRow)="","",INDEX(Curation!$F:$F,_xlpm.srcRow)))} -> 0.125 | F2: {=_xlfn._xlws.SORT(_xlfn.UNIQUE(Table2[Concept]))} -> alma | G2: =IFERROR(SUMIFS(Table2[Frequency],Table2[Concept],$F2,Table2[FeatureNo],G$1),"") -> 6 | H2: =IFERROR(SUMIFS(Table2[Frequency],Table2[Concept],$F2,Table2[FeatureNo],H$1),"") -> 2 | I2: =IFERROR(SUMIFS(Table2[Frequency],Table2[Concept],$F2,Table2[FeatureNo],I$1),"") -> 15 | J2: =IFERROR(SUMIFS(Table2[Frequency],Table2[Concept],$F2,Table2[FeatureNo],J$1),"") -> 13 | K2: =IFERROR(SUMIFS(Table2[Frequency],Table2[Concept],$F2,Table2[FeatureNo],K$1),"") -> 12 | L2: =IFERROR(SUMIFS(Table2[Frequency],Table2[Concept],$F2,Table2[FeatureNo],L$1),"") -> 2 | M2: =IFERROR(SUMIFS(Table2[Frequency],Table2[Concept],$F2,Table2[FeatureNo],M$1),"") -> 2 | N2: =IFERROR(SUMIFS(Table2[Frequency],Table2[Concept],$F2,Table2[FeatureNo],N$1),"") -> 2 | ... P2: =IFERROR(SUMIFS(Table2[Frequency],Table2[Concept],$F2,Table2[FeatureNo],P$1),"") -> 7 | T2: {=_xlfn._xlws.SORT(_xlfn.UNIQUE(Table2[Concept]))} -> alma | U2: =IFERROR(SUMIFS(Table2[Distinct],Table2[Concept],$F2,Table2[FeatureNo],U$1),"") -> 0.125 | V2: =IFERROR(SUMIFS(Table2[Distinct],Table2[Concept],$F2,Table2[FeatureNo],V$1),"") -> 0.111 | W2: =IFERROR(SUMIFS(Table2[Distinct],Table2[Concept],$F2,Table2[FeatureNo],W$1),"") -> 0.125 | X2: =IFERROR(SUMIFS(Table2[Distinct],Table2[Concept],$F2,Table2[FeatureNo],X$1),"") -> 0.111 | Y2: =IFERROR(SUMIFS(Table2[Distinct],Table2[Concept],$F2,Table2[FeatureNo],Y$1),"") -> 0.25 | Z2: =IFERROR(SUMIFS(Table2[Distinct],Table2[Concept],$F2,Table2[FeatureNo],Z$1),"") -> 0.2 | AA2: =IFERROR(SUMIFS(Table2[Distinct],Table2[Concept],$F2,Table2[FeatureNo],AA$1),"") -> 0.2 | AB2: =IFERROR(SUMIFS(Table2[Distinct],Table2[Concept],$F2,Table2[FeatureNo],AB$1),"") -> 0.091 | ... AD2: =IFERROR(SUMIFS(Table2[Distinct],Table2[Concept],$F2,Table2[FeatureNo],AD$1),"") -> 0.2
A3: {=_xlfn.LET(_xlpm.n,ROWS(A$2:A3),_xlpm.block,QUOTIENT(_xlpm.n-1,10),_xlpm.conceptRow,6+_xlpm.block*11,IF(INDEX(Curation!$A:$A,_xlpm.conceptRow)="","",INDEX(Curation!$A:$A,_xlpm.conceptRow)))} -> alma | B3: feature2 | C3: {=_xlfn.LET(_xlpm.n,ROWS(C$2:C3),_xlpm.block,QUOTIENT(_xlpm.n-1,10),_xlpm.pos,MOD(_xlpm.n-1,10),_xlpm.conceptRow,6+_xlpm.block*11,_xlpm.srcRow,_xlpm.conceptRow+_xlpm.pos,IF(INDEX(Curation!$A:$A,_xlpm.conceptRow)="","",INDEX(Curation!$E:$E,_xlpm.srcRow)))} -> 2 | D3: {=_xlfn.LET(_xlpm.n,ROWS(D$2:D3),_xlpm.block,QUOTIENT(_xlpm.n-1,10),_xlpm.pos,MOD(_xlpm.n-1,10),_xlpm.conceptRow,6+_xlpm.block*11,_xlpm.srcRow,_xlpm.conceptRow+_xlpm.pos,IF(INDEX(Curation!$A:$A,_xlpm.conceptRow)="","",INDEX(Curation!$F:$F,_xlpm.srcRow)))} -> 0.111 | F3: asztal | G3: =IFERROR(SUMIFS(Table2[Frequency],Table2[Concept],$F3,Table2[FeatureNo],G$1),"") -> 9 | H3: =IFERROR(SUMIFS(Table2[Frequency],Table2[Concept],$F3,Table2[FeatureNo],H$1),"") -> 12 | I3: =IFERROR(SUMIFS(Table2[Frequency],Table2[Concept],$F3,Table2[FeatureNo],I$1),"") -> 3 | J3: =IFERROR(SUMIFS(Table2[Frequency],Table2[Concept],$F3,Table2[FeatureNo],J$1),"") -> 11 | K3: =IFERROR(SUMIFS(Table2[Frequency],Table2[Concept],$F3,Table2[FeatureNo],K$1),"") -> 5 | L3: =IFERROR(SUMIFS(Table2[Frequency],Table2[Concept],$F3,Table2[FeatureNo],L$1),"") -> 7 | M3: =IFERROR(SUMIFS(Table2[Frequency],Table2[Concept],$F3,Table2[FeatureNo],M$1),"") -> 5 | N3: =IFERROR(SUMIFS(Table2[Frequency],Table2[Concept],$F3,Table2[FeatureNo],N$1),"") -> 3 | ... P3: =IFERROR(SUMIFS(Table2[Frequency],Table2[Concept],$F3,Table2[FeatureNo],P$1),"") -> 11 | T3: asztal | U3: =IFERROR(SUMIFS(Table2[Distinct],Table2[Concept],$F3,Table2[FeatureNo],U$1),"") -> 0.167 | V3: =IFERROR(SUMIFS(Table2[Distinct],Table2[Concept],$F3,Table2[FeatureNo],V$1),"") -> 0.333 | W3: =IFERROR(SUMIFS(Table2[Distinct],Table2[Concept],$F3,Table2[FeatureNo],W$1),"") -> 0.143 | X3: =IFERROR(SUMIFS(Table2[Distinct],Table2[Concept],$F3,Table2[FeatureNo],X$1),"") -> 0.333 | Y3: =IFERROR(SUMIFS(Table2[Distinct],Table2[Concept],$F3,Table2[FeatureNo],Y$1),"") -> 0.125 | Z3: =IFERROR(SUMIFS(Table2[Distinct],Table2[Concept],$F3,Table2[FeatureNo],Z$1),"") -> 0.083 | AA3: =IFERROR(SUMIFS(Table2[Distinct],Table2[Concept],$F3,Table2[FeatureNo],AA$1),"") -> 0.25 | AB3: =IFERROR(SUMIFS(Table2[Distinct],Table2[Concept],$F3,Table2[FeatureNo],AB$1),"") -> 0.2 | ... AD3: =IFERROR(SUMIFS(Table2[Distinct],Table2[Concept],$F3,Table2[FeatureNo],AD$1),"") -> 0.25
A4: {=_xlfn.LET(_xlpm.n,ROWS(A$2:A4),_xlpm.block,QUOTIENT(_xlpm.n-1,10),_xlpm.conceptRow,6+_xlpm.block*11,IF(INDEX(Curation!$A:$A,_xlpm.conceptRow)="","",INDEX(Curation!$A:$A,_xlpm.conceptRow)))} -> alma | B4: feature3 | C4: {=_xlfn.LET(_xlpm.n,ROWS(C$2:C4),_xlpm.block,QUOTIENT(_xlpm.n-1,10),_xlpm.pos,MOD(_xlpm.n-1,10),_xlpm.conceptRow,6+_xlpm.block*11,_xlpm.srcRow,_xlpm.conceptRow+_xlpm.pos,IF(INDEX(Curation!$A:$A,_xlpm.conceptRow)="","",INDEX(Curation!$E:$E,_xlpm.srcRow)))} -> 15 | D4: {=_xlfn.LET(_xlpm.n,ROWS(D$2:D4),_xlpm.block,QUOTIENT(_xlpm.n-1,10),_xlpm.pos,MOD(_xlpm.n-1,10),_xlpm.conceptRow,6+_xlpm.block*11,_xlpm.srcRow,_xlpm.conceptRow+_xlpm.pos,IF(INDEX(Curation!$A:$A,_xlpm.conceptRow)="","",INDEX(Curation!$F:$F,_xlpm.srcRow)))} -> 0.125 | F4: autó | G4: =IFERROR(SUMIFS(Table2[Frequency],Table2[Concept],$F4,Table2[FeatureNo],G$1),"") -> 11 | H4: =IFERROR(SUMIFS(Table2[Frequency],Table2[Concept],$F4,Table2[FeatureNo],H$1),"") -> 3 | I4: =IFERROR(SUMIFS(Table2[Frequency],Table2[Concept],$F4,Table2[FeatureNo],I$1),"") -> 3 | J4: =IFERROR(SUMIFS(Table2[Frequency],Table2[Concept],$F4,Table2[FeatureNo],J$1),"") -> 10 | K4: =IFERROR(SUMIFS(Table2[Frequency],Table2[Concept],$F4,Table2[FeatureNo],K$1),"") -> 6 | L4: =IFERROR(SUMIFS(Table2[Frequency],Table2[Concept],$F4,Table2[FeatureNo],L$1),"") -> 5 | M4: =IFERROR(SUMIFS(Table2[Frequency],Table2[Concept],$F4,Table2[FeatureNo],M$1),"") -> 2 | N4: =IFERROR(SUMIFS(Table2[Frequency],Table2[Concept],$F4,Table2[FeatureNo],N$1),"") -> 1 | ... P4: =IFERROR(SUMIFS(Table2[Frequency],Table2[Concept],$F4,Table2[FeatureNo],P$1),"") -> 5 | T4: autó | U4: =IFERROR(SUMIFS(Table2[Distinct],Table2[Concept],$F4,Table2[FeatureNo],U$1),"") -> 0.333 | V4: =IFERROR(SUMIFS(Table2[Distinct],Table2[Concept],$F4,Table2[FeatureNo],V$1),"") -> 0.333 | W4: =IFERROR(SUMIFS(Table2[Distinct],Table2[Concept],$F4,Table2[FeatureNo],W$1),"") -> 0.143 | X4: =IFERROR(SUMIFS(Table2[Distinct],Table2[Concept],$F4,Table2[FeatureNo],X$1),"") -> 0.2 | Y4: =IFERROR(SUMIFS(Table2[Distinct],Table2[Concept],$F4,Table2[FeatureNo],Y$1),"") -> 0.333 | Z4: =IFERROR(SUMIFS(Table2[Distinct],Table2[Concept],$F4,Table2[FeatureNo],Z$1),"") -> 0.2 | AA4: =IFERROR(SUMIFS(Table2[Distinct],Table2[Concept],$F4,Table2[FeatureNo],AA$1),"") -> 0.25 | AB4: =IFERROR(SUMIFS(Table2[Distinct],Table2[Concept],$F4,Table2[FeatureNo],AB$1),"") -> 0.05 | ... AD4: =IFERROR(SUMIFS(Table2[Distinct],Table2[Concept],$F4,Table2[FeatureNo],AD$1),"") -> 0.2
A5: {=_xlfn.LET(_xlpm.n,ROWS(A$2:A5),_xlpm.block,QUOTIENT(_xlpm.n-1,10),_xlpm.conceptRow,6+_xlpm.block*11,IF(INDEX(Curation!$A:$A,_xlpm.conceptRow)="","",INDEX(Curation!$A:$A,_xlpm.conceptRow)))} -> alma | B5: feature4 | C5: {=_xlfn.LET(_xlpm.n,ROWS(C$2:C5),_xlpm.block,QUOTIENT(_xlpm.n-1,10),_xlpm.pos,MOD(_xlpm.n-1,10),_xlpm.conceptRow,6+_xlpm.block*11,_xlpm.srcRow,_xlpm.conceptRow+_xlpm.pos,IF(INDEX(Curation!$A:$A,_xlpm.conceptRow)="","",INDEX(Curation!$E:$E,_xlpm.srcRow)))} -> 13 | D5: {=_xlfn.LET(_xlpm.n,ROWS(D$2:D5),_xlpm.block,QUOTIENT(_xlpm.n-1,10),_xlpm.pos,MOD(_xlpm.n-1,10),_xlpm.conceptRow,6+_xlpm.block*11,_xlpm.srcRow,_xlpm.conceptRow+_xlpm.pos,IF(INDEX(Curation!$A:$A,_xlpm.conceptRow)="","",INDEX(Curation!$F:$F,_xlpm.srcRow)))} -> 0.111 | F5: bab | G5: =IFERROR(SUMIFS(Table2[Frequency],Table2[Concept],$F5,Table2[FeatureNo],G$1),"") -> 11 | H5: =IFERROR(SUMIFS(Table2[Frequency],Table2[Concept],$F5,Table2[FeatureNo],H$1),"") -> 2 | I5: =IFERROR(SUMIFS(Table2[Frequency],Table2[Concept],$F5,Table2[FeatureNo],I$1),"") -> 5 | J5: =IFERROR(SUMIFS(Table2[Frequency],Table2[Concept],$F5,Table2[FeatureNo],J$1),"") -> 11 | K5: =IFERROR(SUMIFS(Table2[Frequency],Table2[Concept],$F5,Table2[FeatureNo],K$1),"") -> 2 | L5: =IFERROR(SUMIFS(Table2[Frequency],Table2[Concept],$F5,Table2[FeatureNo],L$1),"") -> 2 | M5: =IFERROR(SUMIFS(Table2[Frequency],Table2[Concept],$F5,Table2[FeatureNo],M$1),"") -> 3 | N5: =IFERROR(SUMIFS(Table2[Frequency],Table2[Concept],$F5,Table2[FeatureNo],N$1),"") -> 4 | ... P5: =IFERROR(SUMIFS(Table2[Frequency],Table2[Concept],$F5,Table2[FeatureNo],P$1),"") -> 1 | T5: bab | U5: =IFERROR(SUMIFS(Table2[Distinct],Table2[Concept],$F5,Table2[FeatureNo],U$1),"") -> 0.125 | V5: =IFERROR(SUMIFS(Table2[Distinct],Table2[Concept],$F5,Table2[FeatureNo],V$1),"") -> 0.25 | W5: =IFERROR(SUMIFS(Table2[Distinct],Table2[Concept],$F5,Table2[FeatureNo],W$1),"") -> 0.1 | X5: =IFERROR(SUMIFS(Table2[Distinct],Table2[Concept],$F5,Table2[FeatureNo],X$1),"") -> 0.091 | Y5: =IFERROR(SUMIFS(Table2[Distinct],Table2[Concept],$F5,Table2[FeatureNo],Y$1),"") -> 0.2 | Z5: =IFERROR(SUMIFS(Table2[Distinct],Table2[Concept],$F5,Table2[FeatureNo],Z$1),"") -> 0.111 | AA5: =IFERROR(SUMIFS(Table2[Distinct],Table2[Concept],$F5,Table2[FeatureNo],AA$1),"") -> 0.091 | AB5: =IFERROR(SUMIFS(Table2[Distinct],Table2[Concept],$F5,Table2[FeatureNo],AB$1),"") -> 0.1 | ... AD5: =IFERROR(SUMIFS(Table2[Distinct],Table2[Concept],$F5,Table2[FeatureNo],AD$1),"") -> 0.333
A6: {=_xlfn.LET(_xlpm.n,ROWS(A$2:A6),_xlpm.block,QUOTIENT(_xlpm.n-1,10),_xlpm.conceptRow,6+_xlpm.block*11,IF(INDEX(Curation!$A:$A,_xlpm.conceptRow)="","",INDEX(Curation!$A:$A,_xlpm.conceptRow)))} -> alma | B6: feature5 | C6: {=_xlfn.LET(_xlpm.n,ROWS(C$2:C6),_xlpm.block,QUOTIENT(_xlpm.n-1,10),_xlpm.pos,MOD(_xlpm.n-1,10),_xlpm.conceptRow,6+_xlpm.block*11,_xlpm.srcRow,_xlpm.conceptRow+_xlpm.pos,IF(INDEX(Curation!$A:$A,_xlpm.conceptRow)="","",INDEX(Curation!$E:$E,_xlpm.srcRow)))} -> 12 | D6: {=_xlfn.LET(_xlpm.n,ROWS(D$2:D6),_xlpm.block,QUOTIENT(_xlpm.n-1,10),_xlpm.pos,MOD(_xlpm.n-1,10),_xlpm.conceptRow,6+_xlpm.block*11,_xlpm.srcRow,_xlpm.conceptRow+_xlpm.pos,IF(INDEX(Curation!$A:$A,_xlpm.conceptRow)="","",INDEX(Curation!$F:$F,_xlpm.srcRow)))} -> 0.25 | F6: ceruza | G6: =IFERROR(SUMIFS(Table2[Frequency],Table2[Concept],$F6,Table2[FeatureNo],G$1),"") -> 6 | H6: =IFERROR(SUMIFS(Table2[Frequency],Table2[Concept],$F6,Table2[FeatureNo],H$1),"") -> 5 | I6: =IFERROR(SUMIFS(Table2[Frequency],Table2[Concept],$F6,Table2[FeatureNo],I$1),"") -> 7 | J6: =IFERROR(SUMIFS(Table2[Frequency],Table2[Concept],$F6,Table2[FeatureNo],J$1),"") -> 4 | K6: =IFERROR(SUMIFS(Table2[Frequency],Table2[Concept],$F6,Table2[FeatureNo],K$1),"") -> 1 | L6: =IFERROR(SUMIFS(Table2[Frequency],Table2[Concept],$F6,Table2[FeatureNo],L$1),"") -> 1 | M6: =IFERROR(SUMIFS(Table2[Frequency],Table2[Concept],$F6,Table2[FeatureNo],M$1),"") -> 2 | N6: =IFERROR(SUMIFS(Table2[Frequency],Table2[Concept],$F6,Table2[FeatureNo],N$1),"") -> 4 | ... P6: =IFERROR(SUMIFS(Table2[Frequency],Table2[Concept],$F6,Table2[FeatureNo],P$1),"") -> 2 | T6: ceruza | U6: =IFERROR(SUMIFS(Table2[Distinct],Table2[Concept],$F6,Table2[FeatureNo],U$1),"") -> 0.333 | V6: =IFERROR(SUMIFS(Table2[Distinct],Table2[Concept],$F6,Table2[FeatureNo],V$1),"") -> 0.333 | W6: =IFERROR(SUMIFS(Table2[Distinct],Table2[Concept],$F6,Table2[FeatureNo],W$1),"") -> 0.2 | X6: =IFERROR(SUMIFS(Table2[Distinct],Table2[Concept],$F6,Table2[FeatureNo],X$1),"") -> 0.167 | Y6: =IFERROR(SUMIFS(Table2[Distinct],Table2[Concept],$F6,Table2[FeatureNo],Y$1),"") -> 0.143 | Z6: =IFERROR(SUMIFS(Table2[Distinct],Table2[Concept],$F6,Table2[FeatureNo],Z$1),"") -> 0.333 | AA6: =IFERROR(SUMIFS(Table2[Distinct],Table2[Concept],$F6,Table2[FeatureNo],AA$1),"") -> 0.125 | AB6: =IFERROR(SUMIFS(Table2[Distinct],Table2[Concept],$F6,Table2[FeatureNo],AB$1),"") -> 0.143 | ... AD6: =IFERROR(SUMIFS(Table2[Distinct],Table2[Concept],$F6,Table2[FeatureNo],AD$1),"") -> 0.1
A7: {=_xlfn.LET(_xlpm.n,ROWS(A$2:A7),_xlpm.block,QUOTIENT(_xlpm.n-1,10),_xlpm.conceptRow,6+_xlpm.block*11,IF(INDEX(Curation!$A:$A,_xlpm.conceptRow)="","",INDEX(Curation!$A:$A,_xlpm.conceptRow)))} -> alma | B7: feature6 | C7: {=_xlfn.LET(_xlpm.n,ROWS(C$2:C7),_xlpm.block,QUOTIENT(_xlpm.n-1,10),_xlpm.pos,MOD(_xlpm.n-1,10),_xlpm.conceptRow,6+_xlpm.block*11,_xlpm.srcRow,_xlpm.conceptRow+_xlpm.pos,IF(INDEX(Curation!$A:$A,_xlpm.conceptRow)="","",INDEX(Curation!$E:$E,_xlpm.srcRow)))} -> 2 | D7: {=_xlfn.LET(_xlpm.n,ROWS(D$2:D7),_xlpm.block,QUOTIENT(_xlpm.n-1,10),_xlpm.pos,MOD(_xlpm.n-1,10),_xlpm.conceptRow,6+_xlpm.block*11,_xlpm.srcRow,_xlpm.conceptRow+_xlpm.pos,IF(INDEX(Curation!$A:$A,_xlpm.conceptRow)="","",INDEX(Curation!$F:$F,_xlpm.srcRow)))} -> 0.2 | F7: cipő | G7: =IFERROR(SUMIFS(Table2[Frequency],Table2[Concept],$F7,Table2[FeatureNo],G$1),"") -> 15 | H7: =IFERROR(SUMIFS(Table2[Frequency],Table2[Concept],$F7,Table2[FeatureNo],H$1),"") -> 3 | I7: =IFERROR(SUMIFS(Table2[Frequency],Table2[Concept],$F7,Table2[FeatureNo],I$1),"") -> 5 | J7: =IFERROR(SUMIFS(Table2[Frequency],Table2[Concept],$F7,Table2[FeatureNo],J$1),"") -> 4 | K7: =IFERROR(SUMIFS(Table2[Frequency],Table2[Concept],$F7,Table2[FeatureNo],K$1),"") -> 1 | L7: =IFERROR(SUMIFS(Table2[Frequency],Table2[Concept],$F7,Table2[FeatureNo],L$1),"") -> 2 | M7: =IFERROR(SUMIFS(Table2[Frequency],Table2[Concept],$F7,Table2[FeatureNo],M$1),"") -> 4 | N7: =IFERROR(SUMIFS(Table2[Frequency],Table2[Concept],$F7,Table2[FeatureNo],N$1),"") -> 1 | ... P7: =IFERROR(SUMIFS(Table2[Frequency],Table2[Concept],$F7,Table2[FeatureNo],P$1),"") -> 14 | T7: cipő | U7: =IFERROR(SUMIFS(Table2[Distinct],Table2[Concept],$F7,Table2[FeatureNo],U$1),"") -> 0.143 | V7: =IFERROR(SUMIFS(Table2[Distinct],Table2[Concept],$F7,Table2[FeatureNo],V$1),"") -> 0.125 | W7: =IFERROR(SUMIFS(Table2[Distinct],Table2[Concept],$F7,Table2[FeatureNo],W$1),"") -> 0.333 | X7: =IFERROR(SUMIFS(Table2[Distinct],Table2[Concept],$F7,Table2[FeatureNo],X$1),"") -> 0.167 | Y7: =IFERROR(SUMIFS(Table2[Distinct],Table2[Concept],$F7,Table2[FeatureNo],Y$1),"") -> 0.333 | Z7: =IFERROR(SUMIFS(Table2[Distinct],Table2[Concept],$F7,Table2[FeatureNo],Z$1),"") -> 0.25 | AA7: =IFERROR(SUMIFS(Table2[Distinct],Table2[Concept],$F7,Table2[FeatureNo],AA$1),"") -> 0.111 | AB7: =IFERROR(SUMIFS(Table2[Distinct],Table2[Concept],$F7,Table2[FeatureNo],AB$1),"") -> 0.333 | ... AD7: =IFERROR(SUMIFS(Table2[Distinct],Table2[Concept],$F7,Table2[FeatureNo],AD$1),"") -> 0.25
A8: {=_xlfn.LET(_xlpm.n,ROWS(A$2:A8),_xlpm.block,QUOTIENT(_xlpm.n-1,10),_xlpm.conceptRow,6+_xlpm.block*11,IF(INDEX(Curation!$A:$A,_xlpm.conceptRow)="","",INDEX(Curation!$A:$A,_xlpm.conceptRow)))} -> alma | B8: feature7 | C8: {=_xlfn.LET(_xlpm.n,ROWS(C$2:C8),_xlpm.block,QUOTIENT(_xlpm.n-1,10),_xlpm.pos,MOD(_xlpm.n-1,10),_xlpm.conceptRow,6+_xlpm.block*11,_xlpm.srcRow,_xlpm.conceptRow+_xlpm.pos,IF(INDEX(Curation!$A:$A,_xlpm.conceptRow)="","",INDEX(Curation!$E:$E,_xlpm.srcRow)))} -> 2 | D8: {=_xlfn.LET(_xlpm.n,ROWS(D$2:D8),_xlpm.block,QUOTIENT(_xlpm.n-1,10),_xlpm.pos,MOD(_xlpm.n-1,10),_xlpm.conceptRow,6+_xlpm.block*11,_xlpm.srcRow,_xlpm.conceptRow+_xlpm.pos,IF(INDEX(Curation!$A:$A,_xlpm.conceptRow)="","",INDEX(Curation!$F:$F,_xlpm.srcRow)))} -> 0.2 | F8: citrom | G8: =IFERROR(SUMIFS(Table2[Frequency],Table2[Concept],$F8,Table2[FeatureNo],G$1),"") -> 16 | H8: =IFERROR(SUMIFS(Table2[Frequency],Table2[Concept],$F8,Table2[FeatureNo],H$1),"") -> 7 | I8: =IFERROR(SUMIFS(Table2[Frequency],Table2[Concept],$F8,Table2[FeatureNo],I$1),"") -> 16 | J8: =IFERROR(SUMIFS(Table2[Frequency],Table2[Concept],$F8,Table2[FeatureNo],J$1),"") -> 17 | K8: =IFERROR(SUMIFS(Table2[Frequency],Table2[Concept],$F8,Table2[FeatureNo],K$1),"") -> 5 | L8: =IFERROR(SUMIFS(Table2[Frequency],Table2[Concept],$F8,Table2[FeatureNo],L$1),"") -> 2 | M8: =IFERROR(SUMIFS(Table2[Frequency],Table2[Concept],$F8,Table2[FeatureNo],M$1),"") -> 2 | N8: =IFERROR(SUMIFS(Table2[Frequency],Table2[Concept],$F8,Table2[FeatureNo],N$1),"") -> 3 | ... P8: =IFERROR(SUMIFS(Table2[Frequency],Table2[Concept],$F8,Table2[FeatureNo],P$1),"") -> 2 | T8: citrom | U8: =IFERROR(SUMIFS(Table2[Distinct],Table2[Concept],$F8,Table2[FeatureNo],U$1),"") -> 0.25 | V8: =IFERROR(SUMIFS(Table2[Distinct],Table2[Concept],$F8,Table2[FeatureNo],V$1),"") -> 0.125 | W8: =IFERROR(SUMIFS(Table2[Distinct],Table2[Concept],$F8,Table2[FeatureNo],W$1),"") -> 0.167 | X8: =IFERROR(SUMIFS(Table2[Distinct],Table2[Concept],$F8,Table2[FeatureNo],X$1),"") -> 0.333 | Y8: =IFERROR(SUMIFS(Table2[Distinct],Table2[Concept],$F8,Table2[FeatureNo],Y$1),"") -> 0.333 | Z8: =IFERROR(SUMIFS(Table2[Distinct],Table2[Concept],$F8,Table2[FeatureNo],Z$1),"") -> 0.333 | AA8: =IFERROR(SUMIFS(Table2[Distinct],Table2[Concept],$F8,Table2[FeatureNo],AA$1),"") -> 0.2 | AB8: =IFERROR(SUMIFS(Table2[Distinct],Table2[Concept],$F8,Table2[FeatureNo],AB$1),"") -> 0.2 | ... AD8: =IFERROR(SUMIFS(Table2[Distinct],Table2[Concept],$F8,Table2[FeatureNo],AD$1),"") -> 0.2
A9: {=_xlfn.LET(_xlpm.n,ROWS(A$2:A9),_xlpm.block,QUOTIENT(_xlpm.n-1,10),_xlpm.conceptRow,6+_xlpm.block*11,IF(INDEX(Curation!$A:$A,_xlpm.conceptRow)="","",INDEX(Curation!$A:$A,_xlpm.conceptRow)))} -> alma | B9: feature8 | C9: {=_xlfn.LET(_xlpm.n,ROWS(C$2:C9),_xlpm.block,QUOTIENT(_xlpm.n-1,10),_xlpm.pos,MOD(_xlpm.n-1,10),_xlpm.conceptRow,6+_xlpm.block*11,_xlpm.srcRow,_xlpm.conceptRow+_xlpm.pos,IF(INDEX(Curation!$A:$A,_xlpm.conceptRow)="","",INDEX(Curation!$E:$E,_xlpm.srcRow)))} -> 2 | D9: {=_xlfn.LET(_xlpm.n,ROWS(D$2:D9),_xlpm.block,QUOTIENT(_xlpm.n-1,10),_xlpm.pos,MOD(_xlpm.n-1,10),_xlpm.conceptRow,6+_xlpm.block*11,_xlpm.srcRow,_xlpm.conceptRow+_xlpm.pos,IF(INDEX(Curation!$A:$A,_xlpm.conceptRow)="","",INDEX(Curation!$F:$F,_xlpm.srcRow)))} -> 0.091 | F9: eper | G9: =IFERROR(SUMIFS(Table2[Frequency],Table2[Concept],$F9,Table2[FeatureNo],G$1),"") -> 11 | H9: =IFERROR(SUMIFS(Table2[Frequency],Table2[Concept],$F9,Table2[FeatureNo],H$1),"") -> 8 | I9: =IFERROR(SUMIFS(Table2[Frequency],Table2[Concept],$F9,Table2[FeatureNo],I$1),"") -> 1 | J9: =IFERROR(SUMIFS(Table2[Frequency],Table2[Concept],$F9,Table2[FeatureNo],J$1),"") -> 13 | K9: =IFERROR(SUMIFS(Table2[Frequency],Table2[Concept],$F9,Table2[FeatureNo],K$1),"") -> 3 | L9: =IFERROR(SUMIFS(Table2[Frequency],Table2[Concept],$F9,Table2[FeatureNo],L$1),"") -> 10 | M9: =IFERROR(SUMIFS(Table2[Frequency],Table2[Concept],$F9,Table2[FeatureNo],M$1),"") -> 15 | N9: =IFERROR(SUMIFS(Table2[Frequency],Table2[Concept],$F9,Table2[FeatureNo],N$1),"") -> 3 | ... P9: =IFERROR(SUMIFS(Table2[Frequency],Table2[Concept],$F9,Table2[FeatureNo],P$1),"") -> 3 | T9: eper | U9: =IFERROR(SUMIFS(Table2[Distinct],Table2[Concept],$F9,Table2[FeatureNo],U$1),"") -> 0.125 | V9: =IFERROR(SUMIFS(Table2[Distinct],Table2[Concept],$F9,Table2[FeatureNo],V$1),"") -> 0.25 | W9: =IFERROR(SUMIFS(Table2[Distinct],Table2[Concept],$F9,Table2[FeatureNo],W$1),"") -> 0.091 | X9: =IFERROR(SUMIFS(Table2[Distinct],Table2[Concept],$F9,Table2[FeatureNo],X$1),"") -> 0.125 | Y9: =IFERROR(SUMIFS(Table2[Distinct],Table2[Concept],$F9,Table2[FeatureNo],Y$1),"") -> 0.333 | Z9: =IFERROR(SUMIFS(Table2[Distinct],Table2[Concept],$F9,Table2[FeatureNo],Z$1),"") -> 0.2 | AA9: =IFERROR(SUMIFS(Table2[Distinct],Table2[Concept],$F9,Table2[FeatureNo],AA$1),"") -> 0.333 | AB9: =IFERROR(SUMIFS(Table2[Distinct],Table2[Concept],$F9,Table2[FeatureNo],AB$1),"") -> 0.091 | ... AD9: =IFERROR(SUMIFS(Table2[Distinct],Table2[Concept],$F9,Table2[FeatureNo],AD$1),"") -> 0.111
A10: {=_xlfn.LET(_xlpm.n,ROWS(A$2:A10),_xlpm.block,QUOTIENT(_xlpm.n-1,10),_xlpm.conceptRow,6+_xlpm.block*11,IF(INDEX(Curation!$A:$A,_xlpm.conceptRow)="","",INDEX(Curation!$A:$A,_xlpm.conceptRow)))} -> alma | B10: feature9 | C10: {=_xlfn.LET(_xlpm.n,ROWS(C$2:C10),_xlpm.block,QUOTIENT(_xlpm.n-1,10),_xlpm.pos,MOD(_xlpm.n-1,10),_xlpm.conceptRow,6+_xlpm.block*11,_xlpm.srcRow,_xlpm.conceptRow+_xlpm.pos,IF(INDEX(Curation!$A:$A,_xlpm.conceptRow)="","",INDEX(Curation!$E:$E,_xlpm.srcRow)))} -> 11 | D10: {=_xlfn.LET(_xlpm.n,ROWS(D$2:D10),_xlpm.block,QUOTIENT(_xlpm.n-1,10),_xlpm.pos,MOD(_xlpm.n-1,10),_xlpm.conceptRow,6+_xlpm.block*11,_xlpm.srcRow,_xlpm.conceptRow+_xlpm.pos,IF(INDEX(Curation!$A:$A,_xlpm.conceptRow)="","",INDEX(Curation!$F:$F,_xlpm.srcRow)))} -> 0.2 | F10: erdő | G10: =IFERROR(SUMIFS(Table2[Frequency],Table2[Concept],$F10,Table2[FeatureNo],G$1),"") -> 3 | H10: =IFERROR(SUMIFS(Table2[Frequency],Table2[Concept],$F10,Table2[FeatureNo],H$1),"") -> 2 | I10: =IFERROR(SUMIFS(Table2[Frequency],Table2[Concept],$F10,Table2[FeatureNo],I$1),"") -> 2 | J10: =IFERROR(SUMIFS(Table2[Frequency],Table2[Concept],$F10,Table2[FeatureNo],J$1),"") -> 2 | K10: =IFERROR(SUMIFS(Table2[Frequency],Table2[Concept],$F10,Table2[FeatureNo],K$1),"") -> 4 | L10: =IFERROR(SUMIFS(Table2[Frequency],Table2[Concept],$F10,Table2[FeatureNo],L$1),"") -> 2 | M10: =IFERROR(SUMIFS(Table2[Frequency],Table2[Concept],$F10,Table2[FeatureNo],M$1),"") -> 1 | N10: =IFERROR(SUMIFS(Table2[Frequency],Table2[Concept],$F10,Table2[FeatureNo],N$1),"") -> 4 | ... P10: =IFERROR(SUMIFS(Table2[Frequency],Table2[Concept],$F10,Table2[FeatureNo],P$1),"") -> 1 | T10: erdő | U10: =IFERROR(SUMIFS(Table2[Distinct],Table2[Concept],$F10,Table2[FeatureNo],U$1),"") -> 0.2 | V10: =IFERROR(SUMIFS(Table2[Distinct],Table2[Concept],$F10,Table2[FeatureNo],V$1),"") -> 0.2 | W10: =IFERROR(SUMIFS(Table2[Distinct],Table2[Concept],$F10,Table2[FeatureNo],W$1),"") -> 0.333 | X10: =IFERROR(SUMIFS(Table2[Distinct],Table2[Concept],$F10,Table2[FeatureNo],X$1),"") -> 0.05 | Y10: =IFERROR(SUMIFS(Table2[Distinct],Table2[Concept],$F10,Table2[FeatureNo],Y$1),"") -> 0.333 | Z10: =IFERROR(SUMIFS(Table2[Distinct],Table2[Concept],$F10,Table2[FeatureNo],Z$1),"") -> 0.167 | AA10: =IFERROR(SUMIFS(Table2[Distinct],Table2[Concept],$F10,Table2[FeatureNo],AA$1),"") -> 0.333 | AB10: =IFERROR(SUMIFS(Table2[Distinct],Table2[Concept],$F10,Table2[FeatureNo],AB$1),"") -> 0.25 | ... AD10: =IFERROR(SUMIFS(Table2[Distinct],Table2[Concept],$F10,Table2[FeatureNo],AD$1),"") -> 0.091
A11: {=_xlfn.LET(_xlpm.n,ROWS(A$2:A11),_xlpm.block,QUOTIENT(_xlpm.n-1,10),_xlpm.conceptRow,6+_xlpm.block*11,IF(INDEX(Curation!$A:$A,_xlpm.conceptRow)="","",INDEX(Curation!$A:$A,_xlpm.conceptRow)))} -> alma | B11: feature10 | C11: {=_xlfn.LET(_xlpm.n,ROWS(C$2:C11),_xlpm.block,QUOTIENT(_xlpm.n-1,10),_xlpm.pos,MOD(_xlpm.n-1,10),_xlpm.conceptRow,6+_xlpm.block*11,_xlpm.srcRow,_xlpm.conceptRow+_xlpm.pos,IF(INDEX(Curation!$A:$A,_xlpm.conceptRow)="","",INDEX(Curation!$E:$E,_xlpm.srcRow)))} -> 7 | D11: {=_xlfn.LET(_xlpm.n,ROWS(D$2:D11),_xlpm.block,QUOTIENT(_xlpm.n-1,10),_xlpm.pos,MOD(_xlpm.n-1,10),_xlpm.conceptRow,6+_xlpm.block*11,_xlpm.srcRow,_xlpm.conceptRow+_xlpm.pos,IF(INDEX(Curation!$A:$A,_xlpm.conceptRow)="","",INDEX(Curation!$F:$F,_xlpm.srcRow)))} -> 0.2 | F11: gomba | G11: =IFERROR(SUMIFS(Table2[Frequency],Table2[Concept],$F11,Table2[FeatureNo],G$1),"") -> 14 | H11: =IFERROR(SUMIFS(Table2[Frequency],Table2[Concept],$F11,Table2[FeatureNo],H$1),"") -> 12 | I11: =IFERROR(SUMIFS(Table2[Frequency],Table2[Concept],$F11,Table2[FeatureNo],I$1),"") -> 4 | J11: =IFERROR(SUMIFS(Table2[Frequency],Table2[Concept],$F11,Table2[FeatureNo],J$1),"") -> 10 | K11: =IFERROR(SUMIFS(Table2[Frequency],Table2[Concept],$F11,Table2[FeatureNo],K$1),"") -> 2 | L11: =IFERROR(SUMIFS(Table2[Frequency],Table2[Concept],$F11,Table2[FeatureNo],L$1),"") -> 3 | M11: =IFERROR(SUMIFS(Table2[Frequency],Table2[Concept],$F11,Table2[FeatureNo],M$1),"") -> 2 | N11: =IFERROR(SUMIFS(Table2[Frequency],Table2[Concept],$F11,Table2[FeatureNo],N$1),"") -> 2 | ... P11: =IFERROR(SUMIFS(Table2[Frequency],Table2[Concept],$F11,Table2[FeatureNo],P$1),"") -> 2 | T11: gomba | U11: =IFERROR(SUMIFS(Table2[Distinct],Table2[Concept],$F11,Table2[FeatureNo],U$1),"") -> 0.125 | V11: =IFERROR(SUMIFS(Table2[Distinct],Table2[Concept],$F11,Table2[FeatureNo],V$1),"") -> 0.25 | W11: =IFERROR(SUMIFS(Table2[Distinct],Table2[Concept],$F11,Table2[FeatureNo],W$1),"") -> 0.1 | X11: =IFERROR(SUMIFS(Table2[Distinct],Table2[Concept],$F11,Table2[FeatureNo],X$1),"") -> 0.25 | Y11: =IFERROR(SUMIFS(Table2[Distinct],Table2[Concept],$F11,Table2[FeatureNo],Y$1),"") -> 0.1 | Z11: =IFERROR(SUMIFS(Table2[Distinct],Table2[Concept],$F11,Table2[FeatureNo],Z$1),"") -> 0.333 | AA11: =IFERROR(SUMIFS(Table2[Distinct],Table2[Concept],$F11,Table2[FeatureNo],AA$1),"") -> 0.125 | AB11: =IFERROR(SUMIFS(Table2[Distinct],Table2[Concept],$F11,Table2[FeatureNo],AB$1),"") -> 0.25 | ... AD11: =IFERROR(SUMIFS(Table2[Distinct],Table2[Concept],$F11,Table2[FeatureNo],AD$1),"") -> 0.091
A12: {=_xlfn.LET(_xlpm.n,ROWS(A$2:A12),_xlpm.block,QUOTIENT(_xlpm.n-1,10),_xlpm.conceptRow,6+_xlpm.block*11,IF(INDEX(Curation!$A:$A,_xlpm.conceptRow)="","",INDEX(Curation!$A:$A,_xlpm.conceptRow)))} -> asztal | B12: feature1 | C12: {=_xlfn.LET(_xlpm.n,ROWS(C$2:C12),_xlpm.block,QUOTIENT(_xlpm.n-1,10),_xlpm.pos,MOD(_xlpm.n-1,10),_xlpm.conceptRow,6+_xlpm.block*11,_xlpm.srcRow,_xlpm.conceptRow+_xlpm.pos,IF(INDEX(Curation!$A:$A,_xlpm.conceptRow)="","",INDEX(Curation!$E:$E,_xlpm.srcRow)))} -> 9 | D12: {=_xlfn.LET(_xlpm.n,ROWS(D$2:D12),_xlpm.block,QUOTIENT(_xlpm.n-1,10),_xlpm.pos,MOD(_xlpm.n-1,10),_xlpm.conceptRow,6+_xlpm.block*11,_xlpm.srcRow,_xlpm.conceptRow+_xlpm.pos,IF(INDEX(Curation!$A:$A,_xlpm.conceptRow)="","",INDEX(Curation!$F:$F,_xlpm.srcRow)))} -> 0.167 | F12: gyerek | G12: =IFERROR(SUMIFS(Table2[Frequency],Table2[Concept],$F12,Table2[FeatureNo],G$1),"") -> 1 | H12: =IFERROR(SUMIFS(Table2[Frequency],Table2[Concept],$F12,Table2[FeatureNo],H$1),"") -> 9 | I12: =IFERROR(SUMIFS(Table2[Frequency],Table2[Concept],$F12,Table2[FeatureNo],I$1),"") -> 7 | J12: =IFERROR(SUMIFS(Table2[Frequency],Table2[Concept],$F12,Table2[FeatureNo],J$1),"") -> 7 | K12: =IFERROR(SUMIFS(Table2[Frequency],Table2[Concept],$F12,Table2[FeatureNo],K$1),"") -> 7 | L12: =IFERROR(SUMIFS(Table2[Frequency],Table2[Concept],$F12,Table2[FeatureNo],L$1),"") -> 10 | M12: =IFERROR(SUMIFS(Table2[Frequency],Table2[Concept],$F12,Table2[FeatureNo],M$1),"") -> 1 | N12: =IFERROR(SUMIFS(Table2[Frequency],Table2[Concept],$F12,Table2[FeatureNo],N$1),"") -> 7 | ... P12: =IFERROR(SUMIFS(Table2[Frequency],Table2[Concept],$F12,Table2[FeatureNo],P$1),"") -> 2 | T12: gyerek | U12: =IFERROR(SUMIFS(Table2[Distinct],Table2[Concept],$F12,Table2[FeatureNo],U$1),"") -> 0.167 | V12: =IFERROR(SUMIFS(Table2[Distinct],Table2[Concept],$F12,Table2[FeatureNo],V$1),"") -> 0.333 | W12: =IFERROR(SUMIFS(Table2[Distinct],Table2[Concept],$F12,Table2[FeatureNo],W$1),"") -> 0.25 | X12: =IFERROR(SUMIFS(Table2[Distinct],Table2[Concept],$F12,Table2[FeatureNo],X$1),"") -> 0.143 | Y12: =IFERROR(SUMIFS(Table2[Distinct],Table2[Concept],$F12,Table2[FeatureNo],Y$1),"") -> 0.333 | Z12: =IFERROR(SUMIFS(Table2[Distinct],Table2[Concept],$F12,Table2[FeatureNo],Z$1),"") -> 0.1 | AA12: =IFERROR(SUMIFS(Table2[Distinct],Table2[Concept],$F12,Table2[FeatureNo],AA$1),"") -> 0.25 | AB12: =IFERROR(SUMIFS(Table2[Distinct],Table2[Concept],$F12,Table2[FeatureNo],AB$1),"") -> 0.143 | ... AD12: =IFERROR(SUMIFS(Table2[Distinct],Table2[Concept],$F12,Table2[FeatureNo],AD$1),"") -> 0.333
A13: {=_xlfn.LET(_xlpm.n,ROWS(A$2:A13),_xlpm.block,QUOTIENT(_xlpm.n-1,10),_xlpm.conceptRow,6+_xlpm.block*11,IF(INDEX(Curation!$A:$A,_xlpm.conceptRow)="","",INDEX(Curation!$A:$A,_xlpm.conceptRow)))} -> asztal | B13: feature2 | C13: {=_xlfn.LET(_xlpm.n,ROWS(C$2:C13),_xlpm.block,QUOTIENT(_xlpm.n-1,10),_xlpm.pos,MOD(_xlpm.n-1,10),_xlpm.conceptRow,6+_xlpm.block*11,_xlpm.srcRow,_xlpm.conceptRow+_xlpm.pos,IF(INDEX(Curation!$A:$A,_xlpm.conceptRow)="","",INDEX(Curation!$E:$E,_xlpm.srcRow)))} -> 12 | D13: {=_xlfn.LET(_xlpm.n,ROWS(D$2:D13),_xlpm.block,QUOTIENT(_xlpm.n-1,10),_xlpm.pos,MOD(_xlpm.n-1,10),_xlpm.conceptRow,6+_xlpm.block*11,_xlpm.srcRow,_xlpm.conceptRow+_xlpm.pos,IF(INDEX(Curation!$A:$A,_xlpm.conceptRow)="","",INDEX(Curation!$F:$F,_xlpm.srcRow)))} -> 0.333 | F13: helikopter | G13: =IFERROR(SUMIFS(Table2[Frequency],Table2[Concept],$F13,Table2[FeatureNo],G$1),"") -> 3 | H13: =IFERROR(SUMIFS(Table2[Frequency],Table2[Concept],$F13,Table2[FeatureNo],H$1),"") -> 4 | I13: =IFERROR(SUMIFS(Table2[Frequency],Table2[Concept],$F13,Table2[FeatureNo],I$1),"") -> 1 | J13: =IFERROR(SUMIFS(Table2[Frequency],Table2[Concept],$F13,Table2[FeatureNo],J$1),"") -> 2 | K13: =IFERROR(SUMIFS(Table2[Frequency],Table2[Concept],$F13,Table2[FeatureNo],K$1),"") -> 5 | L13: =IFERROR(SUMIFS(Table2[Frequency],Table2[Concept],$F13,Table2[FeatureNo],L$1),"") -> 3 | M13: =IFERROR(SUMIFS(Table2[Frequency],Table2[Concept],$F13,Table2[FeatureNo],M$1),"") -> 1 | N13: =IFERROR(SUMIFS(Table2[Frequency],Table2[Concept],$F13,Table2[FeatureNo],N$1),"") -> 13 | ... P13: =IFERROR(SUMIFS(Table2[Frequency],Table2[Concept],$F13,Table2[FeatureNo],P$1),"") -> 1 | T13: helikopter | U13: =IFERROR(SUMIFS(Table2[Distinct],Table2[Concept],$F13,Table2[FeatureNo],U$1),"") -> 0.143 | V13: =IFERROR(SUMIFS(Table2[Distinct],Table2[Concept],$F13,Table2[FeatureNo],V$1),"") -> 0.333 | W13: =IFERROR(SUMIFS(Table2[Distinct],Table2[Concept],$F13,Table2[FeatureNo],W$1),"") -> 0.333 | X13: =IFERROR(SUMIFS(Table2[Distinct],Table2[Concept],$F13,Table2[FeatureNo],X$1),"") -> 0.333 | Y13: =IFERROR(SUMIFS(Table2[Distinct],Table2[Concept],$F13,Table2[FeatureNo],Y$1),"") -> 0.25 | Z13: =IFERROR(SUMIFS(Table2[Distinct],Table2[Concept],$F13,Table2[FeatureNo],Z$1),"") -> 0.05 | AA13: =IFERROR(SUMIFS(Table2[Distinct],Table2[Concept],$F13,Table2[FeatureNo],AA$1),"") -> 0.2 | AB13: =IFERROR(SUMIFS(Table2[Distinct],Table2[Concept],$F13,Table2[FeatureNo],AB$1),"") -> 0.2 | ... AD13: =IFERROR(SUMIFS(Table2[Distinct],Table2[Concept],$F13,Table2[FeatureNo],AD$1),"") -> 0.25
A14: {=_xlfn.LET(_xlpm.n,ROWS(A$2:A14),_xlpm.block,QUOTIENT(_xlpm.n-1,10),_xlpm.conceptRow,6+_xlpm.block*11,IF(INDEX(Curation!$A:$A,_xlpm.conceptRow)="","",INDEX(Curation!$A:$A,_xlpm.conceptRow)))} -> asztal | B14: feature3 | C14: {=_xlfn.LET(_xlpm.n,ROWS(C$2:C14),_xlpm.block,QUOTIENT(_xlpm.n-1,10),_xlpm.pos,MOD(_xlpm.n-1,10),_xlpm.conceptRow,6+_xlpm.block*11,_xlpm.srcRow,_xlpm.conceptRow+_xlpm.pos,IF(INDEX(Curation!$A:$A,_xlpm.conceptRow)="","",INDEX(Curation!$E:$E,_xlpm.srcRow)))} -> 3 | D14: {=_xlfn.LET(_xlpm.n,ROWS(D$2:D14),_xlpm.block,QUOTIENT(_xlpm.n-1,10),_xlpm.pos,MOD(_xlpm.n-1,10),_xlpm.conceptRow,6+_xlpm.block*11,_xlpm.srcRow,_xlpm.conceptRow+_xlpm.pos,IF(INDEX(Curation!$A:$A,_xlpm.conceptRow)="","",INDEX(Curation!$F:$F,_xlpm.srcRow)))} -> 0.143 | F14: hercegnő | G14: =IFERROR(SUMIFS(Table2[Frequency],Table2[Concept],$F14,Table2[FeatureNo],G$1),"") -> 3 | H14: =IFERROR(SUMIFS(Table2[Frequency],Table2[Concept],$F14,Table2[FeatureNo],H$1),"") -> 1 | I14: =IFERROR(SUMIFS(Table2[Frequency],Table2[Concept],$F14,Table2[FeatureNo],I$1),"") -> 1 | J14: =IFERROR(SUMIFS(Table2[Frequency],Table2[Concept],$F14,Table2[FeatureNo],J$1),"") -> 1 | K14: =IFERROR(SUMIFS(Table2[Frequency],Table2[Concept],$F14,Table2[FeatureNo],K$1),"") -> 9 | L14: =IFERROR(SUMIFS(Table2[Frequency],Table2[Concept],$F14,Table2[FeatureNo],L$1),"") -> 1 | M14: =IFERROR(SUMIFS(Table2[Frequency],Table2[Concept],$F14,Table2[FeatureNo],M$1),"") -> 1 | N14: =IFERROR(SUMIFS(Table2[Frequency],Table2[Concept],$F14,Table2[FeatureNo],N$1),"") -> 1 | ... P14: =IFERROR(SUMIFS(Table2[Frequency],Table2[Concept],$F14,Table2[FeatureNo],P$1),"") -> 3 | T14: hercegnő | U14: =IFERROR(SUMIFS(Table2[Distinct],Table2[Concept],$F14,Table2[FeatureNo],U$1),"") -> 0.2 | V14: =IFERROR(SUMIFS(Table2[Distinct],Table2[Concept],$F14,Table2[FeatureNo],V$1),"") -> 0.25 | W14: =IFERROR(SUMIFS(Table2[Distinct],Table2[Concept],$F14,Table2[FeatureNo],W$1),"") -> 0.143 | X14: =IFERROR(SUMIFS(Table2[Distinct],Table2[Concept],$F14,Table2[FeatureNo],X$1),"") -> 0.333 | Y14: =IFERROR(SUMIFS(Table2[Distinct],Table2[Concept],$F14,Table2[FeatureNo],Y$1),"") -> 0.333 | Z14: =IFERROR(SUMIFS(Table2[Distinct],Table2[Concept],$F14,Table2[FeatureNo],Z$1),"") -> 0.333 | AA14: =IFERROR(SUMIFS(Table2[Distinct],Table2[Concept],$F14,Table2[FeatureNo],AA$1),"") -> 0.25 | AB14: =IFERROR(SUMIFS(Table2[Distinct],Table2[Concept],$F14,Table2[FeatureNo],AB$1),"") -> 0.167 | ... AD14: =IFERROR(SUMIFS(Table2[Distinct],Table2[Concept],$F14,Table2[FeatureNo],AD$1),"") -> 0.333
... A31: {=_xlfn.LET(_xlpm.n,ROWS(A$2:A31),_xlpm.block,QUOTIENT(_xlpm.n-1,10),_xlpm.conceptRow,6+_xlpm.block*11,IF(INDEX(Curation!$A:$A,_xlpm.conceptRow)="","",INDEX(Curation!$A:$A,_xlpm.conceptRow)))} -> autó | B31: feature10 | C31: {=_xlfn.LET(_xlpm.n,ROWS(C$2:C31),_xlpm.block,QUOTIENT(_xlpm.n-1,10),_xlpm.pos,MOD(_xlpm.n-1,10),_xlpm.conceptRow,6+_xlpm.block*11,_xlpm.srcRow,_xlpm.conceptRow+_xlpm.pos,IF(INDEX(Curation!$A:$A,_xlpm.conceptRow)="","",INDEX(Curation!$E:$E,_xlpm.srcRow)))} -> 5 | D31: {=_xlfn.LET(_xlpm.n,ROWS(D$2:D31),_xlpm.block,QUOTIENT(_xlpm.n-1,10),_xlpm.pos,MOD(_xlpm.n-1,10),_xlpm.conceptRow,6+_xlpm.block*11,_xlpm.srcRow,_xlpm.conceptRow+_xlpm.pos,IF(INDEX(Curation!$A:$A,_xlpm.conceptRow)="","",INDEX(Curation!$F:$F,_xlpm.srcRow)))} -> 0.2 | F31: vonat | G31: =IFERROR(SUMIFS(Table2[Frequency],Table2[Concept],$F31,Table2[FeatureNo],G$1),"") -> 6 | H31: =IFERROR(SUMIFS(Table2[Frequency],Table2[Concept],$F31,Table2[FeatureNo],H$1),"") -> 5 | I31: =IFERROR(SUMIFS(Table2[Frequency],Table2[Concept],$F31,Table2[FeatureNo],I$1),"") -> 4 | J31: =IFERROR(SUMIFS(Table2[Frequency],Table2[Concept],$F31,Table2[FeatureNo],J$1),"") -> 3 | K31: =IFERROR(SUMIFS(Table2[Frequency],Table2[Concept],$F31,Table2[FeatureNo],K$1),"") -> 3 | L31: =IFERROR(SUMIFS(Table2[Frequency],Table2[Concept],$F31,Table2[FeatureNo],L$1),"") -> 17 | M31: =IFERROR(SUMIFS(Table2[Frequency],Table2[Concept],$F31,Table2[FeatureNo],M$1),"") -> 2 | N31: =IFERROR(SUMIFS(Table2[Frequency],Table2[Concept],$F31,Table2[FeatureNo],N$1),"") -> 2 | ... P31: =IFERROR(SUMIFS(Table2[Frequency],Table2[Concept],$F31,Table2[FeatureNo],P$1),"") -> 5 | T31: vonat | U31: =IFERROR(SUMIFS(Table2[Distinct],Table2[Concept],$F31,Table2[FeatureNo],U$1),"") -> 0.333 | V31: =IFERROR(SUMIFS(Table2[Distinct],Table2[Concept],$F31,Table2[FeatureNo],V$1),"") -> 0.143 | W31: =IFERROR(SUMIFS(Table2[Distinct],Table2[Concept],$F31,Table2[FeatureNo],W$1),"") -> 0.05 | X31: =IFERROR(SUMIFS(Table2[Distinct],Table2[Concept],$F31,Table2[FeatureNo],X$1),"") -> 0.25 | Y31: =IFERROR(SUMIFS(Table2[Distinct],Table2[Concept],$F31,Table2[FeatureNo],Y$1),"") -> 0.2 | Z31: =IFERROR(SUMIFS(Table2[Distinct],Table2[Concept],$F31,Table2[FeatureNo],Z$1),"") -> 0.167 | AA31: =IFERROR(SUMIFS(Table2[Distinct],Table2[Concept],$F31,Table2[FeatureNo],AA$1),"") -> 0.333 | AB31: =IFERROR(SUMIFS(Table2[Distinct],Table2[Concept],$F31,Table2[FeatureNo],AB$1),"") -> 0.2 | ... AD31: =IFERROR(SUMIFS(Table2[Distinct],Table2[Concept],$F31,Table2[FeatureNo],AD$1),"") -> 0.333
A32: {=_xlfn.LET(_xlpm.n,ROWS(A$2:A32),_xlpm.block,QUOTIENT(_xlpm.n-1,10),_xlpm.conceptRow,6+_xlpm.block*11,IF(INDEX(Curation!$A:$A,_xlpm.conceptRow)="","",INDEX(Curation!$A:$A,_xlpm.conceptRow)))} -> bab | B32: feature1 | C32: {=_xlfn.LET(_xlpm.n,ROWS(C$2:C32),_xlpm.block,QUOTIENT(_xlpm.n-1,10),_xlpm.pos,MOD(_xlpm.n-1,10),_xlpm.conceptRow,6+_xlpm.block*11,_xlpm.srcRow,_xlpm.conceptRow+_xlpm.pos,IF(INDEX(Curation!$A:$A,_xlpm.conceptRow)="","",INDEX(Curation!$E:$E,_xlpm.srcRow)))} -> 11 | D32: {=_xlfn.LET(_xlpm.n,ROWS(D$2:D32),_xlpm.block,QUOTIENT(_xlpm.n-1,10),_xlpm.pos,MOD(_xlpm.n-1,10),_xlpm.conceptRow,6+_xlpm.block*11,_xlpm.srcRow,_xlpm.conceptRow+_xlpm.pos,IF(INDEX(Curation!$A:$A,_xlpm.conceptRow)="","",INDEX(Curation!$F:$F,_xlpm.srcRow)))} -> 0.125 | F32: 0 | T32: 0
A33: {=_xlfn.LET(_xlpm.n,ROWS(A$2:A33),_xlpm.block,QUOTIENT(_xlpm.n-1,10),_xlpm.conceptRow,6+_xlpm.block*11,IF(INDEX(Curation!$A:$A,_xlpm.conceptRow)="","",INDEX(Curation!$A:$A,_xlpm.conceptRow)))} -> bab | B33: feature2 | C33: {=_xlfn.LET(_xlpm.n,ROWS(C$2:C33),_xlpm.block,QUOTIENT(_xlpm.n-1,10),_xlpm.pos,MOD(_xlpm.n-1,10),_xlpm.conceptRow,6+_xlpm.block*11,_xlpm.srcRow,_xlpm.conceptRow+_xlpm.pos,IF(INDEX(Curation!$A:$A,_xlpm.conceptRow)="","",INDEX(Curation!$E:$E,_xlpm.srcRow)))} -> 2 | D33: {=_xlfn.LET(_xlpm.n,ROWS(D$2:D33),_xlpm.block,QUOTIENT(_xlpm.n-1,10),_xlpm.pos,MOD(_xlpm.n-1,10),_xlpm.conceptRow,6+_xlpm.block*11,_xlpm.srcRow,_xlpm.conceptRow+_xlpm.pos,IF(INDEX(Curation!$A:$A,_xlpm.conceptRow)="","",INDEX(Curation!$F:$F,_xlpm.srcRow)))} -> 0.25
A34: {=_xlfn.LET(_xlpm.n,ROWS(A$2:A34),_xlpm.block,QUOTIENT(_xlpm.n-1,10),_xlpm.conceptRow,6+_xlpm.block*11,IF(INDEX(Curation!$A:$A,_xlpm.conceptRow)="","",INDEX(Curation!$A:$A,_xlpm.conceptRow)))} -> bab | B34: feature3 | C34: {=_xlfn.LET(_xlpm.n,ROWS(C$2:C34),_xlpm.block,QUOTIENT(_xlpm.n-1,10),_xlpm.pos,MOD(_xlpm.n-1,10),_xlpm.conceptRow,6+_xlpm.block*11,_xlpm.srcRow,_xlpm.conceptRow+_xlpm.pos,IF(INDEX(Curation!$A:$A,_xlpm.conceptRow)="","",INDEX(Curation!$E:$E,_xlpm.srcRow)))} -> 5 | D34: {=_xlfn.LET(_xlpm.n,ROWS(D$2:D34),_xlpm.block,QUOTIENT(_xlpm.n-1,10),_xlpm.pos,MOD(_xlpm.n-1,10),_xlpm.conceptRow,6+_xlpm.block*11,_xlpm.srcRow,_xlpm.conceptRow+_xlpm.pos,IF(INDEX(Curation!$A:$A,_xlpm.conceptRow)="","",INDEX(Curation!$F:$F,_xlpm.srcRow)))} -> 0.1 | F34: Bin | G34: {=IFERROR(INDEX($F$2:$F$31,COLUMNS($G:G)),"")} -> alma | H34: {=IFERROR(INDEX($F$2:$F$31,COLUMNS($G:H)),"")} -> asztal | I34: {=IFERROR(INDEX($F$2:$F$31,COLUMNS($G:I)),"")} -> autó | J34: {=IFERROR(INDEX($F$2:$F$31,COLUMNS($G:J)),"")} -> bab | K34: {=IFERROR(INDEX($F$2:$F$31,COLUMNS($G:K)),"")} -> ceruza | L34: {=IFERROR(INDEX($F$2:$F$31,COLUMNS($G:L)),"")} -> cipő | M34: {=IFERROR(INDEX($F$2:$F$31,COLUMNS($G:M)),"")} -> citrom | N34: {=IFERROR(INDEX($F$2:$F$31,COLUMNS($G:N)),"")} -> eper | O34: {=IFERROR(INDEX($F$2:$F$31,COLUMNS($G:O)),"")} -> erdő | P34: {=IFERROR(INDEX($F$2:$F$31,COLUMNS($G:P)),"")} -> gomba | Q34: {=IFERROR(INDEX($F$2:$F$31,COLUMNS($G:Q)),"")} -> gyerek | R34: {=IFERROR(INDEX($F$2:$F$31,COLUMNS($G:R)),"")} -> helikopter | S34: {=IFERROR(INDEX($F$2:$F$31,COLUMNS($G:S)),"")} -> hercegnő | T34: {=IFERROR(INDEX($F$2:$F$31,COLUMNS($G:T)),"")} -> játszótér | U34: {=IFERROR(INDEX($F$2:$F$31,COLUMNS($G:U)),"")} -> kacsa | V34: {=IFERROR(INDEX($F$2:$F$31,COLUMNS($G:V)),"")} -> kard | W34: {=IFERROR(INDEX($F$2:$F$31,COLUMNS($G:W)),"")} -> kéz | X34: {=IFERROR(INDEX($F$2:$F$31,COLUMNS($G:X)),"")} -> könyv | Y34: {=IFERROR(INDEX($F$2:$F$31,COLUMNS($G:Y)),"")} -> krumpli | Z34: {=IFERROR(INDEX($F$2:$F$31,COLUMNS($G:Z)),"")} -> kutya | AA34: {=IFERROR(INDEX($F$2:$F$31,COLUMNS($G:AA)),"")} -> láb | AB34: {=IFERROR(INDEX($F$2:$F$31,COLUMNS($G:AB)),"")} -> ló | AC34: {=IFERROR(INDEX($F$2:$F$31,COLUMNS($G:AC)),"")} -> nadrág | AD34: {=IFERROR(INDEX($F$2:$F$31,COLUMNS($G:AD)),"")} -> nappali | AE34: {=IFERROR(INDEX($F$2:$F$31,COLUMNS($G:AE)),"")} -> pulóver | AF34: {=IFERROR(INDEX($F$2:$F$31,COLUMNS($G:AF)),"")} -> seprű | AG34: {=IFERROR(INDEX($F$2:$F$31,COLUMNS($G:AG)),"")} -> szem | AH34: {=IFERROR(INDEX($F$2:$F$31,COLUMNS($G:AH)),"")} -> szőnyeg | AI34: {=IFERROR(INDEX($F$2:$F$31,COLUMNS($G:AI)),"")} -> tűzoltó | AJ34: {=IFERROR(INDEX($F$2:$F$31,COLUMNS($G:AJ)),"")} -> vonat
A35: {=_xlfn.LET(_xlpm.n,ROWS(A$2:A35),_xlpm.block,QUOTIENT(_xlpm.n-1,10),_xlpm.conceptRow,6+_xlpm.block*11,IF(INDEX(Curation!$A:$A,_xlpm.conceptRow)="","",INDEX(Curation!$A:$A,_xlpm.conceptRow)))} -> bab | B35: feature4 | C35: {=_xlfn.LET(_xlpm.n,ROWS(C$2:C35),_xlpm.block,QUOTIENT(_xlpm.n-1,10),_xlpm.pos,MOD(_xlpm.n-1,10),_xlpm.conceptRow,6+_xlpm.block*11,_xlpm.srcRow,_xlpm.conceptRow+_xlpm.pos,IF(INDEX(Curation!$A:$A,_xlpm.conceptRow)="","",INDEX(Curation!$E:$E,_xlpm.srcRow)))} -> 11 | D35: {=_xlfn.LET(_xlpm.n,ROWS(D$2:D35),_xlpm.block,QUOTIENT(_xlpm.n-1,10),_xlpm.pos,MOD(_xlpm.n-1,10),_xlpm.conceptRow,6+_xlpm.block*11,_xlpm.srcRow,_xlpm.conceptRow+_xlpm.pos,IF(INDEX(Curation!$A:$A,_xlpm.conceptRow)="","",INDEX(Curation!$F:$F,_xlpm.srcRow)))} -> 0.091 | F35: 0 | G35: {=IF(G$34="","",_xlfn.LET(_xlpm.r,INDEX($G$2:$P$31,MATCH(G$34,$F$2:$F$31,0),0),_xlpm.mn,MIN(_xlpm.r),_xlpm.mx,MAX(_xlpm.r),_xlpm.w,(_xlpm.mx-_xlpm.mn)/5,_xlpm.b,$F35,IF(_xlpm.mx=_xlpm.mn,IF(_xlpm.b=0,COUNT(_xlpm.r),0),SUMPRODUCT((_xlpm.r>=_xlpm.mn+_xlpm.b*_xlpm.w)*(_xlpm.r<_xlpm.mn+(_xlpm.b+1)*_xlpm.w))+IF(_xlpm.b=4,SUMPRODUCT(--(_xlpm.r=_xlpm.mx)),0))))} -> 4 | H35: {=IF(H$34="","",_xlfn.LET(_xlpm.r,INDEX($G$2:$P$31,MATCH(H$34,$F$2:$F$31,0),0),_xlpm.mn,MIN(_xlpm.r),_xlpm.mx,MAX(_xlpm.r),_xlpm.w,(_xlpm.mx-_xlpm.mn)/5,_xlpm.b,$F35,IF(_xlpm.mx=_xlpm.mn,IF(_xlpm.b=0,COUNT(_xlpm.r),0),SUMPRODUCT((_xlpm.r>=_xlpm.mn+_xlpm.b*_xlpm.w)*(_xlpm.r<_xlpm.mn+(_xlpm.b+1)*_xlpm.w))+IF(_xlpm.b=4,SUMPRODUCT(--(_xlpm.r=_xlpm.mx)),0))))} -> 3 | I35: {=IF(I$34="","",_xlfn.LET(_xlpm.r,INDEX($G$2:$P$31,MATCH(I$34,$F$2:$F$31,0),0),_xlpm.mn,MIN(_xlpm.r),_xlpm.mx,MAX(_xlpm.r),_xlpm.w,(_xlpm.mx-_xlpm.mn)/5,_xlpm.b,$F35,IF(_xlpm.mx=_xlpm.mn,IF(_xlpm.b=0,COUNT(_xlpm.r),0),SUMPRODUCT((_xlpm.r>=_xlpm.mn+_xlpm.b*_xlpm.w)*(_xlpm.r<_xlpm.mn+(_xlpm.b+1)*_xlpm.w))+IF(_xlpm.b=4,SUMPRODUCT(--(_xlpm.r=_xlpm.mx)),0))))} -> 3 | J35: {=IF(J$34="","",_xlfn.LET(_xlpm.r,INDEX($G$2:$P$31,MATCH(J$34,$F$2:$F$31,0),0),_xlpm.mn,MIN(_xlpm.r),_xlpm.mx,MAX(_xlpm.r),_xlpm.w,(_xlpm.mx-_xlpm.mn)/5,_xlpm.b,$F35,IF(_xlpm.mx=_xlpm.mn,IF(_xlpm.b=0,COUNT(_xlpm.r),0),SUMPRODUCT((_xlpm.r>=_xlpm.mn+_xlpm.b*_xlpm.w)*(_xlpm.r<_xlpm.mn+(_xlpm.b+1)*_xlpm.w))+IF(_xlpm.b=4,SUMPRODUCT(--(_xlpm.r=_xlpm.mx)),0))))} -> 4 | K35: {=IF(K$34="","",_xlfn.LET(_xlpm.r,INDEX($G$2:$P$31,MATCH(K$34,$F$2:$F$31,0),0),_xlpm.mn,MIN(_xlpm.r),_xlpm.mx,MAX(_xlpm.r),_xlpm.w,(_xlpm.mx-_xlpm.mn)/5,_xlpm.b,$F35,IF(_xlpm.mx=_xlpm.mn,IF(_xlpm.b=0,COUNT(_xlpm.r),0),SUMPRODUCT((_xlpm.r>=_xlpm.mn+_xlpm.b*_xlpm.w)*(_xlpm.r<_xlpm.mn+(_xlpm.b+1)*_xlpm.w))+IF(_xlpm.b=4,SUMPRODUCT(--(_xlpm.r=_xlpm.mx)),0))))} -> 4 | L35: {=IF(L$34="","",_xlfn.LET(_xlpm.r,INDEX($G$2:$P$31,MATCH(L$34,$F$2:$F$31,0),0),_xlpm.mn,MIN(_xlpm.r),_xlpm.mx,MAX(_xlpm.r),_xlpm.w,(_xlpm.mx-_xlpm.mn)/5,_xlpm.b,$F35,IF(_xlpm.mx=_xlpm.mn,IF(_xlpm.b=0,COUNT(_xlpm.r),0),SUMPRODUCT((_xlpm.r>=_xlpm.mn+_xlpm.b*_xlpm.w)*(_xlpm.r<_xlpm.mn+(_xlpm.b+1)*_xlpm.w))+IF(_xlpm.b=4,SUMPRODUCT(--(_xlpm.r=_xlpm.mx)),0))))} -> 4 | M35: {=IF(M$34="","",_xlfn.LET(_xlpm.r,INDEX($G$2:$P$31,MATCH(M$34,$F$2:$F$31,0),0),_xlpm.mn,MIN(_xlpm.r),_xlpm.mx,MAX(_xlpm.r),_xlpm.w,(_xlpm.mx-_xlpm.mn)/5,_xlpm.b,$F35,IF(_xlpm.mx=_xlpm.mn,IF(_xlpm.b=0,COUNT(_xlpm.r),0),SUMPRODUCT((_xlpm.r>=_xlpm.mn+_xlpm.b*_xlpm.w)*(_xlpm.r<_xlpm.mn+(_xlpm.b+1)*_xlpm.w))+IF(_xlpm.b=4,SUMPRODUCT(--(_xlpm.r=_xlpm.mx)),0))))} -> 5 | N35: {=IF(N$34="","",_xlfn.LET(_xlpm.r,INDEX($G$2:$P$31,MATCH(N$34,$F$2:$F$31,0),0),_xlpm.mn,MIN(_xlpm.r),_xlpm.mx,MAX(_xlpm.r),_xlpm.w,(_xlpm.mx-_xlpm.mn)/5,_xlpm.b,$F35,IF(_xlpm.mx=_xlpm.mn,IF(_xlpm.b=0,COUNT(_xlpm.r),0),SUMPRODUCT((_xlpm.r>=_xlpm.mn+_xlpm.b*_xlpm.w)*(_xlpm.r<_xlpm.mn+(_xlpm.b+1)*_xlpm.w))+IF(_xlpm.b=4,SUMPRODUCT(--(_xlpm.r=_xlpm.mx)),0))))} -> 5 | ... AJ35: {=IF(AJ$34="","",_xlfn.LET(_xlpm.r,INDEX($G$2:$P$31,MATCH(AJ$34,$F$2:$F$31,0),0),_xlpm.mn,MIN(_xlpm.r),_xlpm.mx,MAX(_xlpm.r),_xlpm.w,(_xlpm.mx-_xlpm.mn)/5,_xlpm.b,$F35,IF(_xlpm.mx=_xlpm.mn,IF(_xlpm.b=0,COUNT(_xlpm.r),0),SUMPRODUCT((_xlpm.r>=_xlpm.mn+_xlpm.b*_xlpm.w)*(_xlpm.r<_xlpm.mn+(_xlpm.b+1)*_xlpm.w))+IF(_xlpm.b=4,SUMPRODUCT(--(_xlpm.r=_xlpm.mx)),0))))} -> 5
